Workbook

Sheet Staffing
B2: Insert the Logos
A4: IP Name
A5: Improving Sustainability and Resilience for Food Production System in Karamoja
A6: LIST OF THE PROJECT MEMBERS OF STAFF
B7: Name | C7: Gender | D7: Function | E7: Place | F7: Telephone Number | G7: Remarks

Sheet FFS groups
A2: ID | B2: Vendor No | C2: IPName | D2: Project | E2: District | F2: Subcounty | G2: Parish | H2: Host Village | I2: Registered group name | J2: FFS Status | K2: Formed with support from | L2: Year Formed | M2: GPS_Eastings | N2: GPS_Northings | Q2: Contact person | R2: Phone number | S2: Old facilitator | T2: New Facilitator | U2: Sex | V2: Contact details | W2: Membership at formation | Z2: Current registered members | AC2: Group identity/legal records | AL2: Financial/phyisical records | AQ2: Learning activities/production records | AY2: Livelihood diversification activities | BH2: Seed multiplication | BU2: Sustainability mechanisms
O3: GPS_Eastings | P3: GPS_Northings | V3: Phone | W3: Male | X3: Female | Z3: Male2 | AA3: Female3 | AB3: Total4 | AC3: Group has a profile | AD3: Group is registered? | AE3: Registering institution | AF3: Registration certificate # | AG3: Date of Issue | AH3: Expiry date | AI3: Constitution | AJ3: Members register | AK3: Minute book | AL3: Bank account | AM3: Cash book | AN3: Savings & credit ledger | AO3: Assets inventory/ register | AP3: VSL Box | AQ3: Season-long learning calender | AR3: Group Action Plan | AS3: Conducted validation studies | AT3: Type of study enterprise | AU3: Main production problem addressed by the study | AV3: Main solutions tested | AW3: Status of the comparative study | AX3: Technology/practice selected for scaling up based on the study | AY3: Type of livelihood interventions supported | AZ3: Types of inputs provided | BA3: Units of measure | BB3: Qty of inputs | BC3: Unit cost of inputs (UGX) | BD3: Total cost (UGX) | BE3: Input beneficiary type | BF3: # of beneficiaries | BG3: Actual/expected yield/revenue | BH3: Type of crop seed provided | BI3: Variety | BJ3: Units of measure5 | BK3: Qty of inputs6 | BL3: Unit cost of inputs7 | BM3: Total cost (UGX)8 | BN3: Input beneficiary type9 | BO3: # of beneficiaries10 | BP3: Qty of seed planted | BQ3: Area planted | BR3: Expected yeld (specify units) | BS3: Actual yeld (specify units) | BT3: How are other group members benefiting from the seeds | BU3: Group has been linked to other opportunities? | BV3: Type of goods or services the group has been linked to (List) | BW3: Types of organizations offering the good or services | BX3: List the names of the institutions linked to the group | BY3: Has the group registered any success stories? | BZ3: # of success stories documented | CA3: Types of success stories documented (List) | CB3: # of documented success stories submitted to FAO | CC3: Types of success stories submitted to FAO (List)2
A4: AMUD-AMUD01
A5: KOT-KOT02
A6: KOT-KOT03
A7: KOT-KOT04
A8: KOT-KOT05
A9: KOT-KOT06
A10: KOT-KOT07
A11: KOT-KOT08
A12: KOT-KOT09
A13: KOT-KOT10
A14: KOT-KOT11
A15: KOT-KOT12
... A66: KOT-PAN31
W67: 686 | X67: 1214 | Y67: 1900

Sheet Sub County-beneficiaries 
A1: ID | B1: DISTRICT | C1: Sub county | D1: Parish | E1: Home Village | F1: Group Name | G1: Name Of Beneficiary | H1: Sex | I1: Year of data collection | J1: Birth year if NIN is correct | K1: Calculated age if NIN is correct | L1: Calculated birth year existing age. | M1: Age | N1: Age group | O1: Updated NIN | P1: NIN length | Q1: Contacts | R1: ccDesignation | S1: Other positions held in the community | T1: Highest level of educ | U1: Marital status | V1: Hh head? | W1: Vulnerabiity status | X1: HH size | Y1: # of adults in hh | Z1: # of children <18 years in hh | AA1: # of boys <18 years in school | AB1: # of girls < 18 years in school | AC1: Level of education for children < 18 years | AD1: Main productive assets possessed at start of the project | AE1: Uses SLM/CSA practices | AF1: Type of land SLM/CSA is being practiced | AG1: Types of SLM/CSA technologies practiced at hh | AH1: Qty of SLM structured created | AI1: Estimated area of land technologies have been applied | AJ1: Estimated increase in crop yields (specify crop and increase in yield) | AK1: Other observed benefits from application of SLM/CSA technologies | AL1: Main productive assets acquired during the course of the project2

Sheet Sub County-II-beneficiaries 
A1: ID | B1: DISTRICT | C1: Sub county | D1: Parish | E1: Home Village | F1: Group Name | G1: Name Of Beneficiary | H1: Sex | I1: Year of data collection | J1: Birth year if NIN is correct | K1: Calculated age if NIN is correct | L1: Calculated birth year existing age. | M1: Age | N1: Age group | O1: Updated NIN | P1: NIN length | Q1: Contacts | R1: ccDesignation | S1: Other positions held in the community | T1: Highest level of educ | U1: Marital status | V1: Hh head? | W1: Vulnerabiity status | X1: HH size | Y1: # of adults in hh | Z1: # of children <18 years in hh | AA1: # of boys <18 years in school | AB1: # of girls < 18 years in school | AC1: Level of education for children < 18 years | AD1: Main productive assets possessed at start of the project | AE1: Uses SLM/CSA practices | AF1: Type of land SLM/CSA is being practiced | AG1: Types of SLM/CSA technologies practiced at hh | AH1: Qty of SLM structured created | AI1: Estimated area of land technologies have been applied | AJ1: Estimated increase in crop yields (specify crop and increase in yield) | AK1: Other observed benefits from application of SLM/CSA technologies | AL1: Main productive assets acquired during the course of the project2

Sheet Sub County III-beneficiaries
A1: ID | B1: DISTRICT | C1: Sub county | D1: Parish | E1: Home Village | F1: Group Name | G1: Name Of Beneficiary | H1: Sex | I1: Year of data collection | J1: Birth year if NIN is correct | K1: Calculated age if NIN is correct | L1: Calculated birth year existing age. | M1: Age | N1: Age group | O1: Updated NIN | P1: NIN length | Q1: Contacts | R1: ccDesignation | S1: Other positions held in the community | T1: Highest level of educ | U1: Marital status | V1: Hh head? | W1: Vulnerabiity status | X1: HH size | Y1: # of adults in hh | Z1: # of children <18 years in hh | AA1: # of boys <18 years in school | AB1: # of girls < 18 years in school | AC1: Level of education for children < 18 years | AD1: Main productive assets possessed at start of the project | AE1: Uses SLM/CSA practices | AF1: Type of land SLM/CSA is being practiced | AG1: Types of SLM/CSA technologies practiced at hh | AH1: Qty of SLM structured created | AI1: Estimated area of land technologies have been applied | AJ1: Estimated increase in crop yields (specify crop and increase in yield) | AK1: Other observed benefits from application of SLM/CSA technologies | AL1: Main productive assets acquired during the course of the project2

Sheet Sub County IV-Beneficiaries
A1: ID | B1: District | C1: Sub county | D1: Parish | E1: Home Village | F1: FFS Group Name | G1: Beneficiary Name | H1: Sex | I1: Year of data collection | J1: Birth year if NIN is correct | K1: Calculated age if NIN is correct | L1: Calculated birth year existing age. | M1: Age | N1: Age group | O1: Updated NIN | P1: NIN length | Q1: Contacts | R1: Designation | S1: Other positions held in the community | T1: Highest level of educ | U1: Marital status | V1: Hh head? | W1: Vulnerabiity status | X1: HH size | Y1: # of adults in hh | Z1: # of children <18 years in hh | AA1: # of boys <18 years in school | AB1: # of girls < 18 years in school | AC1: Level of education for children < 18 years | AD1: Main productive assets possessed at start of the project | AE1: Uses SLM/CSA practices | AF1: Type of land SLM/CSA is being practiced | AG1: Types of SLM/CSA technologies practiced at hh | AH1: Qty of SLM structured created | AI1: Estimated area of land technologies have been applied | AJ1: Estimated increase in crop yields (specify crop and increase in yield) | AK1: Other observed benefits from application of SLM/CSA technologies | AL1: Main productive assets acquired during the course of the project2 | AM1: Type of land SLM/CSA is being practiced | AN1: Types of SLM/CSA technologies practiced at hh | AO1: Qty of SLM structured created | AP1: Estimated area of land technologies have been applied | AQ1: Estimated increase in crop yields (specify crop and increase in yield) | AR1: Other observed benefits from application of SLM/CSA technologies | AS1: Main productive assets acquired during the course of the project2
I942: 2021

Sheet indv savings
J2: Main reason for saving | K2: Main source (s) of income for saving saved | L2: Cycle 1 Action Audit and share out summary | V2: Monthly savings for cycle 2 (UGX)
L3: Share/stamp value (UGX) | M3: Total # of shares bought during the cycle | N3: Total # of shared redeemed | O3: Net # of shares at the end of the cycle | P3: Profits per share | Q3: New share value plus profits | R3: Total amout to be paid out to each member | S3: #/value of share carried forward to next cycle | T3: Total Welfare contributions | V3: Share/stamp value (UGX) | W3: Month 1 | AB3: Month 2 | AF3: Month 3 | AJ3: Month 4 | AN3: Month 5 | AR3: Month 6 | AV3: Month 7 | AZ3: Month 8 | BD3: Month 9 | BH3: Month 10 | BL3: Month 11 | BP3: Month 12 | BT3: Action Audit and share out summary
A4: ID No | B4: District | C4: Sub county | D4: Parish | E4: Home Village | F4: Group Name | G4: Name Of Beneficiary | H4: Sex | I4: NIN | U4: NEW CYCLE OR OLD CYCLE IF NOT SHARED OUT | W4: Date | X4: # of shares at start of the month | Y4: Shares bought during the month | Z4: Redeemed during the month | AA4: Net shares at end of the month | AB4: # of shares at start of the month | AC4: Shares bought during the month | AD4: Redeemed during the month | AE4: Net shares at end of the month | AF4: # of shares at start of the month | AG4: Shares bought during the month | AH4: Redeemed during the month | AI4: Net shares at end of the month | AJ4: # of shares at start of the month | AK4: Shares bought during the month | AL4: Redeemed during the month | AM4: Net shares at end of the month | AN4: # of shares at start of the month | AO4: Shares bought during the month | AP4: # of shares at start of the month | AQ4: Net shares at end of the month | AR4: # of shares at start of the month | AS4: Shares bought during the month | AT4: Redeemed during the month | AU4: Net shares at end of the month | AV4: # of shares at start of the month | AW4: Shares bought during the month | AX4: Redeemed during the month | AY4: Net shares at end of the month | AZ4: # of shares at start of the month | BA4: Shares bought during the month | BB4: Redeemed during the month | BC4: Net shares at end of the month | BD4: # of shares at start of the month | BE4: Shares bought during the month | BF4: Redeemed during the month | BG4: Net shares at end of the month | BH4: # of shares at start of the month | BI4: Shares bought during the month | BJ4: 0 | BK4: Net # of shares at the end of the cycle | BL4: # of shares at start of the month | BM4: Shares bought during the month | BN4: 0 | BO4: Net # of shares at the end of the cycle | BP4: # of shares at start of the month | BQ4: Shares bought during the month | BR4: Redeemed during the month | BS4: Net # of shares at the end of the cycle | BT4: Net # of shares at the end of the cycle | BU4: Profits per share | BV4: New share value plus profits | BW4: Total amout to be paid out to each member | BX4: Date for share out | BY4: #/value of share carried forward to next cycle | BZ4: Welfare contribution

Sheet Group-Savings
K67: 686 | L67: 1214 | M67: 1900 | O67: 117 | P67: 363 | Q67: 540 | R67: 32.61 | T67: 26633 | AC67: =Z67-AB67 -> 0 | AE67: =AC67/V67 -> #DIV/0! | AJ67: =S67+AE67 -> #DIV/0! | AL67: =AJ67*V67 -> #DIV/0! | AN67: =AL67-AM67 -> #DIV/0! | AO67: 0 | AW67: =SUM(AU67:AV67) -> 0 | BB67: =(AY67+AZ67)-BA67 -> 0 | BD67: =BB67 -> 0 | BG67: =(BD67+BE67)-BF67 -> 0 | BI67: =BG67 -> 0 | BL67: =(BI67+BJ67)-BK67 -> 0 | BN67: =BL67 -> 0 | BQ67: =(BN67+BO67)-BP67 -> 0 | BS67: =BQ67 -> 0 | BV67: =(BS67+BT67)-BU67 -> 0 | BX67: =BV67 -> 0 | CA67: =(BX67+BY67)-BZ67 -> 0 | CC67: =CA67 -> 0 | CF67: =(CC67+CD67)-CE67 -> 0 | CH67: =CF67 -> 0 | CK67: =(CH67+CI67)-CJ67 -> 0 | CM67: =CK67 -> 0 | CP67: =(CM67+CN67)-CO67 -> 0 | CR67: =CP67 -> 0 | CU67: =(CR67+CS67)-CT67 -> 0 | CW67: =CU67 -> 0 | CZ67: =(CW67+CX67)-CY67 -> 0 | DB67: =CZ67 -> 0 | DE67: =(DB67+DC67)-DD67 -> 0 | DI67: =DE67 -> 0 | DJ67: =DI67*AX67 -> 0 | DM67: =DK67+DL67 -> 0 | DP67: =DM67-DO67 -> 0
N68: Actuals | O68: 217 | P68: 653 | Q68: 870 | T68: 41688

Sheet Group-Loans
AM1: Kotido sub county
A2: ID No | B2: LoA | C2: IPName | D2: Project | E2: District | F2: Subcounty | G2: Parish | H2: Village | I2: FFS Name | K2: Group membership | N2: Savings start Date | O2: # of Weeks | P2: Members Saving | S2: Interest Rate (%) | AA2: CYCLE 2 OR CYCLE 1 IF NOT SHARED OUT | AB2: Start date for loaning | AC2: # Members borrowing | AG2: Month 1 | AM2: Month 2 | AS2: Month 3 | AY2: Month 4 | BE2: Month 5 | BK2: Month 6 | BQ2: Month 7 | BW2: Month 8 | CC2: Month 9 | CI2: Month 10 | CO2: Month 11 | CU2: Month 12 | DA2: Action audit summary
J3: FFS status | K3: Male | L3: Female | N3: Loaning start date | O3: Saved from inception | R3: Total | T3: Total # of loans issued during the cycle | U3: Total value of Loans disbursed during the cycle1 (A) | V3: Total monthly Interest earned during cycle 1 (B) | W3: Total value of loans issued during cycle 1 (A+B=D) | X3: Total loan amounts recovered during cycle 1 [E] | Y3: Calculated Total outstanding loan amounts not recovered at end of the cycle [D-E) | Z3: Actual Total outstanding loan amounts not yet recovered | AC3: Male | AD3: Female | AE3: Total | AF3: Interest rate (R) | AG3: # of loans disbursed during the month | AH3: Total value of Loans disbursed during the month (A) | AI3: Total monthly Interest for loans issued during the month (B) | AJ3: Total value of loans issued during the month (A+B=D) | AK3: Total loan amount recovered during the month [E] | AL3: Total outstanding loan amounts carried forward [D-E) | AM3: # of loans disbursed during the month | AN3: Total value of Loans disbursed during the month (A) | AO3: Total monthly Interest for loans issued during the month (B) | AP3: Total value of loans issued during the month (A+B=D) | AQ3: Total loan amount recovered during the month [E] | AR3: Total outstanding loan amounts carried forward [D-E) | AS3: # of loans disbursed during the month | AT3: Total value of Loans disbursed during the month (A) | AU3: Total monthly Interest for loans issued during the month (B) | AV3: Total value of loans issued during the month (A+B=D) | AW3: Total loan amount recovered during the month [E] | AX3: Total outstanding loan amounts carried forward [D-E) | AY3: # of loans disbursed during the month | AZ3: Total value of Loans disbursed during the month (A) | BA3: Total monthly Interest for loans issued during the month (B) | BB3: Total value of loans issued during the month (A+B=D) | BC3: Total loan amount recovered during the month [E] | BD3: Total outstanding loan amounts carried forward [D-E) | BE3: # of loans disbursed during the month | BF3: Total value of Loans disbursed during the month (A) | BG3: Total monthly Interest for loans issued during the month (B) | BH3: Total value of loans issued during the month (A+B=D) | BI3: Total loan amount recovered during the month [E] | BJ3: Total outstanding loan amounts carried forward [D-E) | BK3: # of loans disbursed during the month | BL3: Total value of Loans disbursed during the month (A) | BM3: Total monthly Interest for loans issued during the month (B) | BN3: Total value of loans issued during the month (A+B=D) | BO3: Total loan amount recovered during the month [E] | BP3: Total outstanding loan amounts carried forward [D-E) | BQ3: # of loans disbursed during the month | BR3: Total value of Loans disbursed during the month (A) | BS3: Total monthly Interest for loans issued during the month (B) | BT3: Total value of loans issued during the month (A+B=D) | BU3: Total loan amount recovered during the month [E] | BV3: Total outstanding loan amounts carried forward [D-E) | BW3: # of loans disbursed during the month | BX3: Total value of Loans disbursed during the month (A) | BY3: Total monthly Interest for loans issued during the month (B) | BZ3: Total value of loans issued during the month (A+B=D) | CA3: Total loan amount recovered during the month [E] | CB3: Total outstanding loan amounts carried forward [D-E) | CC3: # of loans disbursed during the month | CD3: Total value of Loans disbursed during the month (A) | CE3: Total monthly Interest for loans issued during the month (B) | CF3: Total value of loans issued during the month (A+B=D) | CG3: Total loan amount recovered during the month [E] | CH3: Total outstanding loan amounts carried forward [D-E) | CI3: # of loans disbursed during the month | CJ3: Total value of Loans disbursed during the month (A) | CK3: Total monthly Interest for loans issued during the month (B) | CL3: Total value of loans issued during the month (A+B=D) | CM3: Total loan amount recovered during the month [E] | CN3: Total outstanding loan amounts carried forward [D-E) | CO3: # of loans disbursed during the month | CP3: Total value of Loans disbursed during the month (A) | CQ3: Total monthly Interest for loans issued during the month (B) | CR3: Total value of loans issued during the month (A+B=D) | CS3: Total loan amount recovered during the month [E] | CT3: Total outstanding loan amounts carried forward [D-E) | CU3: # of loans disbursed during the month | CV3: Total value of Loans disbursed during the month (A) | CW3: Total monthly Interest for loans issued during the month (B) | CX3: Total value of loans issued during the month (A+B=D) | CY3: Total loan amount recovered during the month [E] | CZ3: Total outstanding loan amounts carried forward [D-E) | DA3: Total # of loans issued during the cycle | DB3: Cumulative value of Loans disbursed during the cycle1 (A) | DC3: Cumulative monthly Interest earned during cycle 1 (B) | DD3: Cumulative value of loans issued during cycle 1 (A+B=D) | DE3: Cumulative loan amounts recovered during cycle 1 [E] | DF3: Cumulative value of outstanding loan amounts not recovered at end of the cycle [D-E)
A4: ='Group-Savings'!A4 -> 0 | B4: ='Group-Savings'!B4 -> 0 | C4: ='Group-Savings'!C4 -> 0 | D4: ='Group-Savings'!D4 -> 0 | E4: ='Group-Savings'!E4 -> 0 | F4: ='Group-Savings'!F4 -> 0 | G4: ='Group-Savings'!G4 -> 0 | H4: ='Group-Savings'!H4 -> 0 | ... L4: ='Group-Savings'!L4 -> 0 | M4: =K4+L4 -> 0 | O4: 52 | R4: 24 | S4: 10 | U4: 0 | V4: =S4*U4 -> 0 | W4: 1090900 | X4: 1090900 | Y4: =W4-X4 -> 0 | Z4: 198000 | AI4: =$AF$4*AH4 -> 0 | AJ4: =AH4+AI4 -> 0 | AL4: =AJ4-AK4 -> 0 | AO4: =$AF$4*AN4 -> 0 | AP4: =AN4+AO4 -> 0 | AR4: =(AP4-AQ4)+AL4 -> 0 | AU4: =$AF$4*AT4 -> 0 | AV4: =AT4+AU4 -> 0 | AX4: =(AV4-AW4)+AR4 -> 0 | BA4: =$AF$4*AZ4 -> 0 | BB4: =AZ4+BA4 -> 0 | BD4: =(BB4-BC4)+AX4 -> 0 | BG4: =$AF$4*BF4 -> 0 | BH4: =BF4+BG4 -> 0 | BJ4: =(BH4-BI4)+BD4 -> 0 | BM4: =$AF$4*BL4 -> 0 | BN4: =BL4+BM4 -> 0 | BP4: =(BN4-BO4)+BJ4 -> 0 | BS4: =$AF$4*BR4 -> 0 | BT4: =BR4+BS4 -> 0 | BV4: =(BT4-BU4)+BP4 -> 0 | BY4: =$AF$4*BX4 -> 0 | BZ4: =BX4+BY4 -> 0 | CB4: =(BZ4-CA4)+BV4 -> 0 | CE4: =$AF$4*CD4 -> 0 | CF4: =CD4+CE4 -> 0 | CH4: =(CF4-CG4)+CB4 -> 0 | CK4: =$AF$4*CJ4 -> 0 | CL4: =CJ4+CK4 -> 0 | CN4: =(CL4-CM4)+CH4 -> 0 | CQ4: =$AF$4*CP4 -> 0 | CR4: =CP4+CQ4 -> 0 | CT4: =(CR4-CS4)+CN4 -> 0 | CW4: =$AF$4*CV4 -> 0 | CX4: =CV4+CW4 -> 0 | CZ4: =(CX4-CY4)+CT4 -> 0 | DA4: =SUM(AG4,AM4,AS4,AY4,BE4,BK4,BQ4,BW4,CC4,CI4,CO4,CU4) -> 0 | DB4: =SUM(AH4,AN4,AT4,AZ4,BF4,BL4,BR4,BX4,CD4,CJ4,CP4,CV4) -> 0 | DC4: =SUM(AI4,AO4,AU4,BA4,BG4,BM4,BS4,BY4,CE4,CK4,CQ4,CW4) -> 0 | DD4: =SUM(AJ4,AP4,AV4,BB4,BH4,BN4,BT4,BZ4,CF4,CL4,CR4,CX4) -> 0 | DE4: =SUM(AK4,AQ4,AW4,BC4,BI4,BO4,BU4,CA4,CG4,CM4,CS4,CY4) -> 0 | DF4: =CZ4 -> 0
A5: ='Group-Savings'!A5 -> 0 | B5: ='Group-Savings'!B5 -> 0 | C5: ='Group-Savings'!C5 -> 0 | D5: ='Group-Savings'!D5 -> 0 | E5: ='Group-Savings'!E5 -> 0 | F5: ='Group-Savings'!F5 -> 0 | G5: ='Group-Savings'!G5 -> 0 | H5: ='Group-Savings'!H5 -> 0 | ... L5: ='Group-Savings'!L5 -> 0 | M5: =K5+L5 -> 0 | O5: 31 | R5: 12 | S5: 10 | U5: 0 | V5: =S5*U5 -> 0 | W5: 400000 | X5: 400000 | Y5: =W5-X5 -> 0 | Z5: 92000 | AI5: =$AF$5*AH5 -> 0 | AJ5: =AH5+AI5 -> 0 | AL5: =AJ5-AK5 -> 0 | AO5: =$AF$5*AN5 -> 0 | AP5: =AN5+AO5 -> 0 | AR5: =(AP5-AQ5)+AL5 -> 0 | AU5: =$AF$5*AT5 -> 0 | AV5: =AT5+AU5 -> 0 | AX5: =(AV5-AW5)+AR5 -> 0 | BA5: =$AF$5*AZ5 -> 0 | BB5: =AZ5+BA5 -> 0 | BD5: =(BB5-BC5)+AX5 -> 0 | BG5: =$AF$5*BF5 -> 0 | BH5: =BF5+BG5 -> 0 | BJ5: =(BH5-BI5)+BD5 -> 0 | BM5: =$AF$5*BL5 -> 0 | BN5: =BL5+BM5 -> 0 | BP5: =(BN5-BO5)+BJ5 -> 0 | BS5: =$AF$5*BR5 -> 0 | BT5: =BR5+BS5 -> 0 | BV5: =(BT5-BU5)+BP5 -> 0 | BY5: =$AF$5*BX5 -> 0 | BZ5: =BX5+BY5 -> 0 | CB5: =(BZ5-CA5)+BV5 -> 0 | CE5: =$AF$5*CD5 -> 0 | CF5: =CD5+CE5 -> 0 | CH5: =(CF5-CG5)+CB5 -> 0 | CK5: =$AF$5*CJ5 -> 0 | CL5: =CJ5+CK5 -> 0 | CN5: =(CL5-CM5)+CH5 -> 0 | CQ5: =$AF$5*CP5 -> 0 | CR5: =CP5+CQ5 -> 0 | CT5: =(CR5-CS5)+CN5 -> 0 | CW5: =$AF$5*CV5 -> 0 | CX5: =CV5+CW5 -> 0 | CZ5: =(CX5-CY5)+CT5 -> 0 | DA5: =SUM(AG5,AM5,AS5,AY5,BE5,BK5,BQ5,BW5,CC5,CI5,CO5,CU5) -> 0 | DB5: =SUM(AH5,AN5,AT5,AZ5,BF5,BL5,BR5,BX5,CD5,CJ5,CP5,CV5) -> 0 | DC5: =SUM(AI5,AO5,AU5,BA5,BG5,BM5,BS5,BY5,CE5,CK5,CQ5,CW5) -> 0 | DD5: =SUM(AJ5,AP5,AV5,BB5,BH5,BN5,BT5,BZ5,CF5,CL5,CR5,CX5) -> 0 | DE5: =SUM(AK5,AQ5,AW5,BC5,BI5,BO5,BU5,CA5,CG5,CM5,CS5,CY5) -> 0 | DF5: =CZ5 -> 0
A6: ='Group-Savings'!A6 -> 0 | B6: ='Group-Savings'!B6 -> 0 | C6: ='Group-Savings'!C6 -> 0 | D6: ='Group-Savings'!D6 -> 0 | E6: ='Group-Savings'!E6 -> 0 | F6: ='Group-Savings'!F6 -> 0 | G6: ='Group-Savings'!G6 -> 0 | H6: ='Group-Savings'!H6 -> 0 | ... L6: ='Group-Savings'!L6 -> 0 | M6: =K6+L6 -> 0 | O6: 52 | R6: 22 | S6: 10 | V6: =S6*U6 -> 0 | W6: 1990500 | X6: 650000 | Y6: =W6-X6 -> 1340500 | Z6: 124000 | AI6: =$AF$6*AH6 -> 0 | AJ6: =AH6+AI6 -> 0 | AL6: =AJ6-AK6 -> 0 | AO6: =$AF$6*AN6 -> 0 | AP6: =AN6+AO6 -> 0 | AR6: =(AP6-AQ6)+AL6 -> 0 | AU6: =$AF$6*AT6 -> 0 | AV6: =AT6+AU6 -> 0 | AX6: =(AV6-AW6)+AR6 -> 0 | BA6: =$AF$6*AZ6 -> 0 | BB6: =AZ6+BA6 -> 0 | BD6: =(BB6-BC6)+AX6 -> 0 | BG6: =$AF$6*BF6 -> 0 | BH6: =BF6+BG6 -> 0 | BJ6: =(BH6-BI6)+BD6 -> 0 | BM6: =$AF$6*BL6 -> 0 | BN6: =BL6+BM6 -> 0 | BP6: =(BN6-BO6)+BJ6 -> 0 | BS6: =$AF$6*BR6 -> 0 | BT6: =BR6+BS6 -> 0 | BV6: =(BT6-BU6)+BP6 -> 0 | BY6: =$AF$6*BX6 -> 0 | BZ6: =BX6+BY6 -> 0 | CB6: =(BZ6-CA6)+BV6 -> 0 | CE6: =$AF$6*CD6 -> 0 | CF6: =CD6+CE6 -> 0 | CH6: =(CF6-CG6)+CB6 -> 0 | CK6: =$AF$6*CJ6 -> 0 | CL6: =CJ6+CK6 -> 0 | CN6: =(CL6-CM6)+CH6 -> 0 | CQ6: =$AF$6*CP6 -> 0 | CR6: =CP6+CQ6 -> 0 | CT6: =(CR6-CS6)+CN6 -> 0 | CW6: =$AF$6*CV6 -> 0 | CX6: =CV6+CW6 -> 0 | CZ6: =(CX6-CY6)+CT6 -> 0 | DA6: =SUM(AG6,AM6,AS6,AY6,BE6,BK6,BQ6,BW6,CC6,CI6,CO6,CU6) -> 0 | DB6: =SUM(AH6,AN6,AT6,AZ6,BF6,BL6,BR6,BX6,CD6,CJ6,CP6,CV6) -> 0 | DC6: =SUM(AI6,AO6,AU6,BA6,BG6,BM6,BS6,BY6,CE6,CK6,CQ6,CW6) -> 0 | DD6: =SUM(AJ6,AP6,AV6,BB6,BH6,BN6,BT6,BZ6,CF6,CL6,CR6,CX6) -> 0 | DE6: =SUM(AK6,AQ6,AW6,BC6,BI6,BO6,BU6,CA6,CG6,CM6,CS6,CY6) -> 0 | DF6: =CZ6 -> 0
A7: ='Group-Savings'!A7 -> 0 | B7: ='Group-Savings'!B7 -> 0 | C7: ='Group-Savings'!C7 -> 0 | D7: ='Group-Savings'!D7 -> 0 | E7: ='Group-Savings'!E7 -> 0 | F7: ='Group-Savings'!F7 -> 0 | G7: ='Group-Savings'!G7 -> 0 | H7: ='Group-Savings'!H7 -> 0 | ... L7: ='Group-Savings'!L7 -> 0 | M7: =K7+L7 -> 0 | O7: 17 | R7: 20 | S7: 10 | U7: 0 | V7: =S7*U7 -> 0 | W7: 730000 | X7: 730000 | Y7: =W7-X7 -> 0 | Z7: 80000 | AI7: =$AF$7*AH7 -> 0 | AJ7: =AH7+AI7 -> 0 | AL7: =AJ7-AK7 -> 0 | AO7: =$AF$7*AN7 -> 0 | AP7: =AN7+AO7 -> 0 | AR7: =(AP7-AQ7)+AL7 -> 0 | AU7: =$AF$7*AT7 -> 0 | AV7: =AT7+AU7 -> 0 | AX7: =(AV7-AW7)+AR7 -> 0 | BA7: =$AF$7*AZ7 -> 0 | BB7: =AZ7+BA7 -> 0 | BD7: =(BB7-BC7)+AX7 -> 0 | BG7: =$AF$7*BF7 -> 0 | BH7: =BF7+BG7 -> 0 | BJ7: =(BH7-BI7)+BD7 -> 0 | BM7: =$AF$7*BL7 -> 0 | BN7: =BL7+BM7 -> 0 | BP7: =(BN7-BO7)+BJ7 -> 0 | BS7: =$AF$7*BR7 -> 0 | BT7: =BR7+BS7 -> 0 | BV7: =(BT7-BU7)+BP7 -> 0 | BY7: =$AF$7*BX7 -> 0 | BZ7: =BX7+BY7 -> 0 | CB7: =(BZ7-CA7)+BV7 -> 0 | CE7: =$AF$7*CD7 -> 0 | CF7: =CD7+CE7 -> 0 | CH7: =(CF7-CG7)+CB7 -> 0 | CK7: =$AF$7*CJ7 -> 0 | CL7: =CJ7+CK7 -> 0 | CN7: =(CL7-CM7)+CH7 -> 0 | CQ7: =$AF$7*CP7 -> 0 | CR7: =CP7+CQ7 -> 0 | CT7: =(CR7-CS7)+CN7 -> 0 | CW7: =$AF$7*CV7 -> 0 | CX7: =CV7+CW7 -> 0 | CZ7: =(CX7-CY7)+CT7 -> 0 | DA7: =SUM(AG7,AM7,AS7,AY7,BE7,BK7,BQ7,BW7,CC7,CI7,CO7,CU7) -> 0 | DB7: =SUM(AH7,AN7,AT7,AZ7,BF7,BL7,BR7,BX7,CD7,CJ7,CP7,CV7) -> 0 | DC7: =SUM(AI7,AO7,AU7,BA7,BG7,BM7,BS7,BY7,CE7,CK7,CQ7,CW7) -> 0 | DD7: =SUM(AJ7,AP7,AV7,BB7,BH7,BN7,BT7,BZ7,CF7,CL7,CR7,CX7) -> 0 | DE7: =SUM(AK7,AQ7,AW7,BC7,BI7,BO7,BU7,CA7,CG7,CM7,CS7,CY7) -> 0 | DF7: =CZ7 -> 0
A8: ='Group-Savings'!A8 -> 0 | B8: ='Group-Savings'!B8 -> 0 | C8: ='Group-Savings'!C8 -> 0 | D8: ='Group-Savings'!D8 -> 0 | E8: ='Group-Savings'!E8 -> 0 | F8: ='Group-Savings'!F8 -> 0 | G8: ='Group-Savings'!G8 -> 0 | H8: ='Group-Savings'!H8 -> 0 | ... L8: ='Group-Savings'!L8 -> 0 | M8: =K8+L8 -> 0 | O8: 32 | R8: 18 | S8: 10 | V8: =S8*U8 -> 0 | W8: 3000000 | X8: 150000 | Y8: =W8-X8 -> 2850000 | Z8: 120000 | AI8: =$AF$8*AH8 -> 0 | AJ8: =AH8+AI8 -> 0 | AL8: =AJ8-AK8 -> 0 | AO8: =$AF$8*AN8 -> 0 | AP8: =AN8+AO8 -> 0 | AR8: =(AP8-AQ8)+AL8 -> 0 | AU8: =$AF$8*AT8 -> 0 | AV8: =AT8+AU8 -> 0 | AX8: =(AV8-AW8)+AR8 -> 0 | BA8: =$AF$8*AZ8 -> 0 | BB8: =AZ8+BA8 -> 0 | BD8: =(BB8-BC8)+AX8 -> 0 | BG8: =$AF$8*BF8 -> 0 | BH8: =BF8+BG8 -> 0 | BJ8: =(BH8-BI8)+BD8 -> 0 | BM8: =$AF$8*BL8 -> 0 | BN8: =BL8+BM8 -> 0 | BP8: =(BN8-BO8)+BJ8 -> 0 | BS8: =$AF$8*BR8 -> 0 | BT8: =BR8+BS8 -> 0 | BV8: =(BT8-BU8)+BP8 -> 0 | BY8: =$AF$8*BX8 -> 0 | BZ8: =BX8+BY8 -> 0 | CB8: =(BZ8-CA8)+BV8 -> 0 | CE8: =$AF$8*CD8 -> 0 | CF8: =CD8+CE8 -> 0 | CH8: =(CF8-CG8)+CB8 -> 0 | CK8: =$AF$8*CJ8 -> 0 | CL8: =CJ8+CK8 -> 0 | CN8: =(CL8-CM8)+CH8 -> 0 | CQ8: =$AF$8*CP8 -> 0 | CR8: =CP8+CQ8 -> 0 | CT8: =(CR8-CS8)+CN8 -> 0 | CW8: =$AF$8*CV8 -> 0 | CX8: =CV8+CW8 -> 0 | CZ8: =(CX8-CY8)+CT8 -> 0 | DA8: =SUM(AG8,AM8,AS8,AY8,BE8,BK8,BQ8,BW8,CC8,CI8,CO8,CU8) -> 0 | DB8: =SUM(AH8,AN8,AT8,AZ8,BF8,BL8,BR8,BX8,CD8,CJ8,CP8,CV8) -> 0 | DC8: =SUM(AI8,AO8,AU8,BA8,BG8,BM8,BS8,BY8,CE8,CK8,CQ8,CW8) -> 0 | DD8: =SUM(AJ8,AP8,AV8,BB8,BH8,BN8,BT8,BZ8,CF8,CL8,CR8,CX8) -> 0 | DE8: =SUM(AK8,AQ8,AW8,BC8,BI8,BO8,BU8,CA8,CG8,CM8,CS8,CY8) -> 0 | DF8: =CZ8 -> 0
A9: ='Group-Savings'!A9 -> 0 | B9: ='Group-Savings'!B9 -> 0 | C9: ='Group-Savings'!C9 -> 0 | D9: ='Group-Savings'!D9 -> 0 | E9: ='Group-Savings'!E9 -> 0 | F9: ='Group-Savings'!F9 -> 0 | G9: ='Group-Savings'!G9 -> 0 | H9: ='Group-Savings'!H9 -> 0 | ... L9: ='Group-Savings'!L9 -> 0 | M9: =K9+L9 -> 0 | O9: 24 | R9: 13 | S9: 10 | V9: =S9*U9 -> 0 | W9: 300000 | X9: 300000 | Y9: =W9-X9 -> 0 | Z9: 6000 | AI9: =$AF$9*AH9 -> 0 | AJ9: =AH9+AI9 -> 0 | AL9: =AJ9-AK9 -> 0 | AO9: =$AF$9*AN9 -> 0 | AP9: =AN9+AO9 -> 0 | AR9: =(AP9-AQ9)+AL9 -> 0 | AU9: =$AF$9*AT9 -> 0 | AV9: =AT9+AU9 -> 0 | AX9: =(AV9-AW9)+AR9 -> 0 | BA9: =$AF$9*AZ9 -> 0 | BB9: =AZ9+BA9 -> 0 | BD9: =(BB9-BC9)+AX9 -> 0 | BG9: =$AF$9*BF9 -> 0 | BH9: =BF9+BG9 -> 0 | BJ9: =(BH9-BI9)+BD9 -> 0 | BM9: =$AF$9*BL9 -> 0 | BN9: =BL9+BM9 -> 0 | BP9: =(BN9-BO9)+BJ9 -> 0 | BS9: =$AF$9*BR9 -> 0 | BT9: =BR9+BS9 -> 0 | BV9: =(BT9-BU9)+BP9 -> 0 | BY9: =$AF$9*BX9 -> 0 | BZ9: =BX9+BY9 -> 0 | CB9: =(BZ9-CA9)+BV9 -> 0 | CE9: =$AF$9*CD9 -> 0 | CF9: =CD9+CE9 -> 0 | CH9: =(CF9-CG9)+CB9 -> 0 | CK9: =$AF$9*CJ9 -> 0 | CL9: =CJ9+CK9 -> 0 | CN9: =(CL9-CM9)+CH9 -> 0 | CQ9: =$AF$9*CP9 -> 0 | CR9: =CP9+CQ9 -> 0 | CT9: =(CR9-CS9)+CN9 -> 0 | CW9: =$AF$9*CV9 -> 0 | CX9: =CV9+CW9 -> 0 | CZ9: =(CX9-CY9)+CT9 -> 0 | DA9: =SUM(AG9,AM9,AS9,AY9,BE9,BK9,BQ9,BW9,CC9,CI9,CO9,CU9) -> 0 | DB9: =SUM(AH9,AN9,AT9,AZ9,BF9,BL9,BR9,BX9,CD9,CJ9,CP9,CV9) -> 0 | DC9: =SUM(AI9,AO9,AU9,BA9,BG9,BM9,BS9,BY9,CE9,CK9,CQ9,CW9) -> 0 | DD9: =SUM(AJ9,AP9,AV9,BB9,BH9,BN9,BT9,BZ9,CF9,CL9,CR9,CX9) -> 0 | DE9: =SUM(AK9,AQ9,AW9,BC9,BI9,BO9,BU9,CA9,CG9,CM9,CS9,CY9) -> 0 | DF9: =CZ9 -> 0
A10: ='Group-Savings'!A10 -> 0 | B10: ='Group-Savings'!B10 -> 0 | C10: ='Group-Savings'!C10 -> 0 | D10: ='Group-Savings'!D10 -> 0 | E10: ='Group-Savings'!E10 -> 0 | F10: ='Group-Savings'!F10 -> 0 | G10: ='Group-Savings'!G10 -> 0 | H10: ='Group-Savings'!H10 -> 0 | ... L10: ='Group-Savings'!L10 -> 0 | M10: =K10+L10 -> 0 | O10: 40 | R10: 25 | S10: 10 | V10: =S10*U10 -> 0 | W10: 14170000 | X10: 14170000 | Y10: =W10-X10 -> 0 | Z10: 300000 | AI10: =$AF$10*AH10 -> 0 | AJ10: =AH10+AI10 -> 0 | AL10: =AJ10-AK10 -> 0 | AO10: =$AF$10*AN10 -> 0 | AP10: =AN10+AO10 -> 0 | AR10: =(AP10-AQ10)+AL10 -> 0 | AU10: =$AF$10*AT10 -> 0 | AV10: =AT10+AU10 -> 0 | AX10: =(AV10-AW10)+AR10 -> 0 | BA10: =$AF$10*AZ10 -> 0 | BB10: =AZ10+BA10 -> 0 | BD10: =(BB10-BC10)+AX10 -> 0 | BG10: =$AF$10*BF10 -> 0 | BH10: =BF10+BG10 -> 0 | BJ10: =(BH10-BI10)+BD10 -> 0 | BM10: =$AF$10*BL10 -> 0 | BN10: =BL10+BM10 -> 0 | BP10: =(BN10-BO10)+BJ10 -> 0 | BS10: =$AF$10*BR10 -> 0 | BT10: =BR10+BS10 -> 0 | BV10: =(BT10-BU10)+BP10 -> 0 | BY10: =$AF$10*BX10 -> 0 | BZ10: =BX10+BY10 -> 0 | CB10: =(BZ10-CA10)+BV10 -> 0 | CE10: =$AF$10*CD10 -> 0 | CF10: =CD10+CE10 -> 0 | CH10: =(CF10-CG10)+CB10 -> 0 | CK10: =$AF$10*CJ10 -> 0 | CL10: =CJ10+CK10 -> 0 | CN10: =(CL10-CM10)+CH10 -> 0 | CQ10: =$AF$10*CP10 -> 0 | CR10: =CP10+CQ10 -> 0 | CT10: =(CR10-CS10)+CN10 -> 0 | CW10: =$AF$10*CV10 -> 0 | CX10: =CV10+CW10 -> 0 | CZ10: =(CX10-CY10)+CT10 -> 0 | DA10: =SUM(AG10,AM10,AS10,AY10,BE10,BK10,BQ10,BW10,CC10,CI10,CO10,CU10) -> 0 | DB10: =SUM(AH10,AN10,AT10,AZ10,BF10,BL10,BR10,BX10,CD10,CJ10,CP10,CV10) -> 0 | DC10: =SUM(AI10,AO10,AU10,BA10,BG10,BM10,BS10,BY10,CE10,CK10,CQ10,CW10) -> 0 | DD10: =SUM(AJ10,AP10,AV10,BB10,BH10,BN10,BT10,BZ10,CF10,CL10,CR10,CX10) -> 0 | DE10: =SUM(AK10,AQ10,AW10,BC10,BI10,BO10,BU10,CA10,CG10,CM10,CS10,CY10) -> 0 | DF10: =CZ10 -> 0
A11: ='Group-Savings'!A11 -> 0 | B11: ='Group-Savings'!B11 -> 0 | C11: ='Group-Savings'!C11 -> 0 | D11: ='Group-Savings'!D11 -> 0 | E11: ='Group-Savings'!E11 -> 0 | F11: ='Group-Savings'!F11 -> 0 | G11: ='Group-Savings'!G11 -> 0 | H11: ='Group-Savings'!H11 -> 0 | ... L11: ='Group-Savings'!L11 -> 0 | M11: =K11+L11 -> 0 | O11: 22 | R11: 17 | S11: 10 | V11: =S11*U11 -> 0 | W11: 410000 | X11: 370000 | Y11: =W11-X11 -> 40000 | Z11: 45000 | AI11: =$AF$11*AH11 -> 0 | AJ11: =AH11+AI11 -> 0 | AL11: =AJ11-AK11 -> 0 | AO11: =$AF$11*AN11 -> 0 | AP11: =AN11+AO11 -> 0 | AR11: =(AP11-AQ11)+AL11 -> 0 | AU11: =$AF$11*AT11 -> 0 | AV11: =AT11+AU11 -> 0 | AX11: =(AV11-AW11)+AR11 -> 0 | BA11: =$AF$11*AZ11 -> 0 | BB11: =AZ11+BA11 -> 0 | BD11: =(BB11-BC11)+AX11 -> 0 | BG11: =$AF$11*BF11 -> 0 | BH11: =BF11+BG11 -> 0 | BJ11: =(BH11-BI11)+BD11 -> 0 | BM11: =$AF$11*BL11 -> 0 | BN11: =BL11+BM11 -> 0 | BP11: =(BN11-BO11)+BJ11 -> 0 | BS11: =$AF$11*BR11 -> 0 | BT11: =BR11+BS11 -> 0 | BV11: =(BT11-BU11)+BP11 -> 0 | BY11: =$AF$11*BX11 -> 0 | BZ11: =BX11+BY11 -> 0 | CB11: =(BZ11-CA11)+BV11 -> 0 | CE11: =$AF$11*CD11 -> 0 | CF11: =CD11+CE11 -> 0 | CH11: =(CF11-CG11)+CB11 -> 0 | CK11: =$AF$11*CJ11 -> 0 | CL11: =CJ11+CK11 -> 0 | CN11: =(CL11-CM11)+CH11 -> 0 | CQ11: =$AF$11*CP11 -> 0 | CR11: =CP11+CQ11 -> 0 | CT11: =(CR11-CS11)+CN11 -> 0 | CW11: =$AF$11*CV11 -> 0 | CX11: =CV11+CW11 -> 0 | CZ11: =(CX11-CY11)+CT11 -> 0 | DA11: =SUM(AG11,AM11,AS11,AY11,BE11,BK11,BQ11,BW11,CC11,CI11,CO11,CU11) -> 0 | DB11: =SUM(AH11,AN11,AT11,AZ11,BF11,BL11,BR11,BX11,CD11,CJ11,CP11,CV11) -> 0 | DC11: =SUM(AI11,AO11,AU11,BA11,BG11,BM11,BS11,BY11,CE11,CK11,CQ11,CW11) -> 0 | DD11: =SUM(AJ11,AP11,AV11,BB11,BH11,BN11,BT11,BZ11,CF11,CL11,CR11,CX11) -> 0 | DE11: =SUM(AK11,AQ11,AW11,BC11,BI11,BO11,BU11,CA11,CG11,CM11,CS11,CY11) -> 0 | DF11: =CZ11 -> 0
A12: ='Group-Savings'!A12 -> 0 | B12: ='Group-Savings'!B12 -> 0 | C12: ='Group-Savings'!C12 -> 0 | D12: ='Group-Savings'!D12 -> 0 | E12: ='Group-Savings'!E12 -> 0 | F12: ='Group-Savings'!F12 -> 0 | G12: ='Group-Savings'!G12 -> 0 | H12: ='Group-Savings'!H12 -> 0 | ... L12: ='Group-Savings'!L12 -> 0 | M12: =K12+L12 -> 0 | O12: 48 | R12: 27 | S12: 10 | U12: 0 | V12: =S12*U12 -> 0 | W12: 846100 | X12: 441200 | Y12: =W12-X12 -> 404900 | Z12: 115700 | AI12: =$AF$12*AH12 -> 0 | AJ12: =AH12+AI12 -> 0 | AL12: =AJ12-AK12 -> 0 | AO12: =$AF$12*AN12 -> 0 | AP12: =AN12+AO12 -> 0 | AR12: =(AP12-AQ12)+AL12 -> 0 | AU12: =$AF$12*AT12 -> 0 | AV12: =AT12+AU12 -> 0 | AX12: =(AV12-AW12)+AR12 -> 0 | BA12: =$AF$12*AZ12 -> 0 | BB12: =AZ12+BA12 -> 0 | BD12: =(BB12-BC12)+AX12 -> 0 | BG12: =$AF$12*BF12 -> 0 | BH12: =BF12+BG12 -> 0 | BJ12: =(BH12-BI12)+BD12 -> 0 | BM12: =$AF$12*BL12 -> 0 | BN12: =BL12+BM12 -> 0 | BP12: =(BN12-BO12)+BJ12 -> 0 | BS12: =$AF$12*BR12 -> 0 | BT12: =BR12+BS12 -> 0 | BV12: =(BT12-BU12)+BP12 -> 0 | BY12: =$AF$12*BX12 -> 0 | BZ12: =BX12+BY12 -> 0 | CB12: =(BZ12-CA12)+BV12 -> 0 | CE12: =$AF$12*CD12 -> 0 | CF12: =CD12+CE12 -> 0 | CH12: =(CF12-CG12)+CB12 -> 0 | CK12: =$AF$12*CJ12 -> 0 | CL12: =CJ12+CK12 -> 0 | CN12: =(CL12-CM12)+CH12 -> 0 | CQ12: =$AF$12*CP12 -> 0 | CR12: =CP12+CQ12 -> 0 | CT12: =(CR12-CS12)+CN12 -> 0 | CW12: =$AF$12*CV12 -> 0 | CX12: =CV12+CW12 -> 0 | CZ12: =(CX12-CY12)+CT12 -> 0 | DA12: =SUM(AG12,AM12,AS12,AY12,BE12,BK12,BQ12,BW12,CC12,CI12,CO12,CU12) -> 0 | DB12: =SUM(AH12,AN12,AT12,AZ12,BF12,BL12,BR12,BX12,CD12,CJ12,CP12,CV12) -> 0 | DC12: =SUM(AI12,AO12,AU12,BA12,BG12,BM12,BS12,BY12,CE12,CK12,CQ12,CW12) -> 0 | DD12: =SUM(AJ12,AP12,AV12,BB12,BH12,BN12,BT12,BZ12,CF12,CL12,CR12,CX12) -> 0 | DE12: =SUM(AK12,AQ12,AW12,BC12,BI12,BO12,BU12,CA12,CG12,CM12,CS12,CY12) -> 0 | DF12: =CZ12 -> 0
A13: ='Group-Savings'!A13 -> 0 | B13: ='Group-Savings'!B13 -> 0 | C13: ='Group-Savings'!C13 -> 0 | D13: ='Group-Savings'!D13 -> 0 | E13: ='Group-Savings'!E13 -> 0 | F13: ='Group-Savings'!F13 -> 0 | G13: ='Group-Savings'!G13 -> 0 | H13: ='Group-Savings'!H13 -> 0 | ... L13: ='Group-Savings'!L13 -> 0 | M13: =K13+L13 -> 0 | O13: 24 | R13: 25 | S13: 10 | V13: =S13*U13 -> 0 | W13: 566100 | X13: 63900 | Y13: =W13-X13 -> 502200 | Z13: 51000 | AI13: =$AF$13*AH13 -> 0 | AJ13: =AH13+AI13 -> 0 | AL13: =AJ13-AK13 -> 0 | AO13: =$AF$13*AN13 -> 0 | AP13: =AN13+AO13 -> 0 | AR13: =(AP13-AQ13)+AL13 -> 0 | AU13: =$AF$13*AT13 -> 0 | AV13: =AT13+AU13 -> 0 | AX13: =(AV13-AW13)+AR13 -> 0 | BA13: =$AF$13*AZ13 -> 0 | BB13: =AZ13+BA13 -> 0 | BD13: =(BB13-BC13)+AX13 -> 0 | BG13: =$AF$13*BF13 -> 0 | BH13: =BF13+BG13 -> 0 | BJ13: =(BH13-BI13)+BD13 -> 0 | BM13: =$AF$13*BL13 -> 0 | BN13: =BL13+BM13 -> 0 | BP13: =(BN13-BO13)+BJ13 -> 0 | BS13: =$AF$13*BR13 -> 0 | BT13: =BR13+BS13 -> 0 | BV13: =(BT13-BU13)+BP13 -> 0 | BY13: =$AF$13*BX13 -> 0 | BZ13: =BX13+BY13 -> 0 | CB13: =(BZ13-CA13)+BV13 -> 0 | CE13: =$AF$13*CD13 -> 0 | CF13: =CD13+CE13 -> 0 | CH13: =(CF13-CG13)+CB13 -> 0 | CK13: =$AF$13*CJ13 -> 0 | CL13: =CJ13+CK13 -> 0 | CN13: =(CL13-CM13)+CH13 -> 0 | CQ13: =$AF$13*CP13 -> 0 | CR13: =CP13+CQ13 -> 0 | CT13: =(CR13-CS13)+CN13 -> 0 | CW13: =$AF$13*CV13 -> 0 | CX13: =CV13+CW13 -> 0 | CZ13: =(CX13-CY13)+CT13 -> 0 | DA13: =SUM(AG13,AM13,AS13,AY13,BE13,BK13,BQ13,BW13,CC13,CI13,CO13,CU13) -> 0 | DB13: =SUM(AH13,AN13,AT13,AZ13,BF13,BL13,BR13,BX13,CD13,CJ13,CP13,CV13) -> 0 | DC13: =SUM(AI13,AO13,AU13,BA13,BG13,BM13,BS13,BY13,CE13,CK13,CQ13,CW13) -> 0 | DD13: =SUM(AJ13,AP13,AV13,BB13,BH13,BN13,BT13,BZ13,CF13,CL13,CR13,CX13) -> 0 | DE13: =SUM(AK13,AQ13,AW13,BC13,BI13,BO13,BU13,CA13,CG13,CM13,CS13,CY13) -> 0 | DF13: =CZ13 -> 0
A14: ='Group-Savings'!A14 -> 0 | B14: ='Group-Savings'!B14 -> 0 | C14: ='Group-Savings'!C14 -> 0 | D14: ='Group-Savings'!D14 -> 0 | E14: ='Group-Savings'!E14 -> 0 | F14: ='Group-Savings'!F14 -> 0 | G14: ='Group-Savings'!G14 -> 0 | H14: ='Group-Savings'!H14 -> 0 | ... L14: ='Group-Savings'!L14 -> 0 | M14: =K14+L14 -> 0 | O14: 32 | R14: 31 | S14: 10 | U14: 0 | V14: =S14*U14 -> 0 | W14: 822000 | X14: 213800 | Y14: =W14-X14 -> 608200 | Z14: 210000 | AI14: =$AF$14*AH14 -> 0 | AJ14: =AH14+AI14 -> 0 | AL14: =AJ14-AK14 -> 0 | AO14: =$AF$14*AN14 -> 0 | AP14: =AN14+AO14 -> 0 | AR14: =(AP14-AQ14)+AL14 -> 0 | AU14: =$AF$14*AT14 -> 0 | AV14: =AT14+AU14 -> 0 | AX14: =(AV14-AW14)+AR14 -> 0 | BA14: =$AF$14*AZ14 -> 0 | BB14: =AZ14+BA14 -> 0 | BD14: =(BB14-BC14)+AX14 -> 0 | BG14: =$AF$14*BF14 -> 0 | BH14: =BF14+BG14 -> 0 | BJ14: =(BH14-BI14)+BD14 -> 0 | BM14: =$AF$14*BL14 -> 0 | BN14: =BL14+BM14 -> 0 | BP14: =(BN14-BO14)+BJ14 -> 0 | BS14: =$AF$14*BR14 -> 0 | BT14: =BR14+BS14 -> 0 | BV14: =(BT14-BU14)+BP14 -> 0 | BY14: =$AF$14*BX14 -> 0 | BZ14: =BX14+BY14 -> 0 | CB14: =(BZ14-CA14)+BV14 -> 0 | CE14: =$AF$14*CD14 -> 0 | CF14: =CD14+CE14 -> 0 | CH14: =(CF14-CG14)+CB14 -> 0 | CK14: =$AF$14*CJ14 -> 0 | CL14: =CJ14+CK14 -> 0 | CN14: =(CL14-CM14)+CH14 -> 0 | CQ14: =$AF$14*CP14 -> 0 | CR14: =CP14+CQ14 -> 0 | CT14: =(CR14-CS14)+CN14 -> 0 | CW14: =$AF$14*CV14 -> 0 | CX14: =CV14+CW14 -> 0 | CZ14: =(CX14-CY14)+CT14 -> 0 | DA14: =SUM(AG14,AM14,AS14,AY14,BE14,BK14,BQ14,BW14,CC14,CI14,CO14,CU14) -> 0 | DB14: =SUM(AH14,AN14,AT14,AZ14,BF14,BL14,BR14,BX14,CD14,CJ14,CP14,CV14) -> 0 | DC14: =SUM(AI14,AO14,AU14,BA14,BG14,BM14,BS14,BY14,CE14,CK14,CQ14,CW14) -> 0 | DD14: =SUM(AJ14,AP14,AV14,BB14,BH14,BN14,BT14,BZ14,CF14,CL14,CR14,CX14) -> 0 | DE14: =SUM(AK14,AQ14,AW14,BC14,BI14,BO14,BU14,CA14,CG14,CM14,CS14,CY14) -> 0 | DF14: =CZ14 -> 0
A15: ='Group-Savings'!A15 -> 0 | B15: ='Group-Savings'!B15 -> 0 | C15: ='Group-Savings'!C15 -> 0 | D15: ='Group-Savings'!D15 -> 0 | E15: ='Group-Savings'!E15 -> 0 | F15: ='Group-Savings'!F15 -> 0 | G15: ='Group-Savings'!G15 -> 0 | H15: ='Group-Savings'!H15 -> 0 | ... L15: ='Group-Savings'!L15 -> 0 | M15: =K15+L15 -> 0 | O15: 49 | R15: 27 | S15: 10 | U15: 0 | V15: =S15*U15 -> 0 | W15: 955000 | X15: 955000 | Y15: =W15-X15 -> 0 | Z15: 343000 | AI15: =$AF$15*AH15 -> 0 | AJ15: =AH15+AI15 -> 0 | AL15: =AJ15-AK15 -> 0 | AO15: =$AF$15*AN15 -> 0 | AP15: =AN15+AO15 -> 0 | AR15: =(AP15-AQ15)+AL15 -> 0 | AU15: =$AF$15*AT15 -> 0 | AV15: =AT15+AU15 -> 0 | AX15: =(AV15-AW15)+AR15 -> 0 | BA15: =$AF$15*AZ15 -> 0 | BB15: =AZ15+BA15 -> 0 | BD15: =(BB15-BC15)+AX15 -> 0 | BG15: =$AF$15*BF15 -> 0 | BH15: =BF15+BG15 -> 0 | BJ15: =(BH15-BI15)+BD15 -> 0 | BM15: =$AF$15*BL15 -> 0 | BN15: =BL15+BM15 -> 0 | BP15: =(BN15-BO15)+BJ15 -> 0 | BS15: =$AF$15*BR15 -> 0 | BT15: =BR15+BS15 -> 0 | BV15: =(BT15-BU15)+BP15 -> 0 | BY15: =$AF$15*BX15 -> 0 | BZ15: =BX15+BY15 -> 0 | CB15: =(BZ15-CA15)+BV15 -> 0 | CE15: =$AF$15*CD15 -> 0 | CF15: =CD15+CE15 -> 0 | CH15: =(CF15-CG15)+CB15 -> 0 | CK15: =$AF$15*CJ15 -> 0 | CL15: =CJ15+CK15 -> 0 | CN15: =(CL15-CM15)+CH15 -> 0 | CQ15: =$AF$15*CP15 -> 0 | CR15: =CP15+CQ15 -> 0 | CT15: =(CR15-CS15)+CN15 -> 0 | CW15: =$AF$15*CV15 -> 0 | CX15: =CV15+CW15 -> 0 | CZ15: =(CX15-CY15)+CT15 -> 0 | DA15: =SUM(AG15,AM15,AS15,AY15,BE15,BK15,BQ15,BW15,CC15,CI15,CO15,CU15) -> 0 | DB15: =SUM(AH15,AN15,AT15,AZ15,BF15,BL15,BR15,BX15,CD15,CJ15,CP15,CV15) -> 0 | DC15: =SUM(AI15,AO15,AU15,BA15,BG15,BM15,BS15,BY15,CE15,CK15,CQ15,CW15) -> 0 | DD15: =SUM(AJ15,AP15,AV15,BB15,BH15,BN15,BT15,BZ15,CF15,CL15,CR15,CX15) -> 0 | DE15: =SUM(AK15,AQ15,AW15,BC15,BI15,BO15,BU15,CA15,CG15,CM15,CS15,CY15) -> 0 | DF15: =CZ15 -> 0
A16: ='Group-Savings'!A16 -> 0 | B16: ='Group-Savings'!B16 -> 0 | C16: ='Group-Savings'!C16 -> 0 | D16: ='Group-Savings'!D16 -> 0 | E16: ='Group-Savings'!E16 -> 0 | F16: ='Group-Savings'!F16 -> 0 | G16: ='Group-Savings'!G16 -> 0 | H16: ='Group-Savings'!H16 -> 0 | ... L16: ='Group-Savings'!L16 -> 0 | M16: =K16+L16 -> 0 | O16: 31 | R16: 26 | S16: 10 | U16: 0 | V16: =S16*U16 -> 0 | W16: 1190000 | X16: 1110000 | Y16: =W16-X16 -> 80000 | Z16: 230000 | AI16: =$AF$16*AH16 -> 0 | AJ16: =AH16+AI16 -> 0 | AL16: =AJ16-AK16 -> 0 | AO16: =$AF$16*AN16 -> 0 | AP16: =AN16+AO16 -> 0 | AR16: =(AP16-AQ16)+AL16 -> 0 | AU16: =$AF$16*AT16 -> 0 | AV16: =AT16+AU16 -> 0 | AX16: =(AV16-AW16)+AR16 -> 0 | BA16: =$AF$16*AZ16 -> 0 | BB16: =AZ16+BA16 -> 0 | BD16: =(BB16-BC16)+AX16 -> 0 | BG16: =$AF$16*BF16 -> 0 | BH16: =BF16+BG16 -> 0 | BJ16: =(BH16-BI16)+BD16 -> 0 | BM16: =$AF$16*BL16 -> 0 | BN16: =BL16+BM16 -> 0 | BP16: =(BN16-BO16)+BJ16 -> 0 | BS16: =$AF$16*BR16 -> 0 | BT16: =BR16+BS16 -> 0 | BV16: =(BT16-BU16)+BP16 -> 0 | BY16: =$AF$16*BX16 -> 0 | BZ16: =BX16+BY16 -> 0 | CB16: =(BZ16-CA16)+BV16 -> 0 | CE16: =$AF$16*CD16 -> 0 | CF16: =CD16+CE16 -> 0 | CH16: =(CF16-CG16)+CB16 -> 0 | CK16: =$AF$16*CJ16 -> 0 | CL16: =CJ16+CK16 -> 0 | CN16: =(CL16-CM16)+CH16 -> 0 | CQ16: =$AF$16*CP16 -> 0 | CR16: =CP16+CQ16 -> 0 | CT16: =(CR16-CS16)+CN16 -> 0 | CW16: =$AF$16*CV16 -> 0 | CX16: =CV16+CW16 -> 0 | CZ16: =(CX16-CY16)+CT16 -> 0 | DA16: =SUM(AG16,AM16,AS16,AY16,BE16,BK16,BQ16,BW16,CC16,CI16,CO16,CU16) -> 0 | DB16: =SUM(AH16,AN16,AT16,AZ16,BF16,BL16,BR16,BX16,CD16,CJ16,CP16,CV16) -> 0 | DC16: =SUM(AI16,AO16,AU16,BA16,BG16,BM16,BS16,BY16,CE16,CK16,CQ16,CW16) -> 0 | DD16: =SUM(AJ16,AP16,AV16,BB16,BH16,BN16,BT16,BZ16,CF16,CL16,CR16,CX16) -> 0 | DE16: =SUM(AK16,AQ16,AW16,BC16,BI16,BO16,BU16,CA16,CG16,CM16,CS16,CY16) -> 0 | DF16: =CZ16 -> 0
A17: ='Group-Savings'!A17 -> 0 | B17: ='Group-Savings'!B17 -> 0 | C17: ='Group-Savings'!C17 -> 0 | D17: ='Group-Savings'!D17 -> 0 | E17: ='Group-Savings'!E17 -> 0 | F17: ='Group-Savings'!F17 -> 0 | G17: ='Group-Savings'!G17 -> 0 | H17: ='Group-Savings'!H17 -> 0 | ... L17: ='Group-Savings'!L17 -> 0 | M17: =K17+L17 -> 0 | O17: 31 | R17: 21 | S17: 10 | V17: =S17*U17 -> 0 | W17: 331000 | X17: 331000 | Y17: =W17-X17 -> 0 | Z17: 95000 | AI17: =$AF$17*AH17 -> 0 | AJ17: =AH17+AI17 -> 0 | AL17: =AJ17-AK17 -> 0 | AO17: =$AF$17*AN17 -> 0 | AP17: =AN17+AO17 -> 0 | AR17: =(AP17-AQ17)+AL17 -> 0 | AU17: =$AF$17*AT17 -> 0 | AV17: =AT17+AU17 -> 0 | AX17: =(AV17-AW17)+AR17 -> 0 | BA17: =$AF$17*AZ17 -> 0 | BB17: =AZ17+BA17 -> 0 | BD17: =(BB17-BC17)+AX17 -> 0 | BG17: =$AF$17*BF17 -> 0 | BH17: =BF17+BG17 -> 0 | BJ17: =(BH17-BI17)+BD17 -> 0 | BM17: =$AF$17*BL17 -> 0 | BN17: =BL17+BM17 -> 0 | BP17: =(BN17-BO17)+BJ17 -> 0 | BS17: =$AF$17*BR17 -> 0 | BT17: =BR17+BS17 -> 0 | BV17: =(BT17-BU17)+BP17 -> 0 | BY17: =$AF$17*BX17 -> 0 | BZ17: =BX17+BY17 -> 0 | CB17: =(BZ17-CA17)+BV17 -> 0 | CE17: =$AF$17*CD17 -> 0 | CF17: =CD17+CE17 -> 0 | CH17: =(CF17-CG17)+CB17 -> 0 | CK17: =$AF$17*CJ17 -> 0 | CL17: =CJ17+CK17 -> 0 | CN17: =(CL17-CM17)+CH17 -> 0 | CQ17: =$AF$17*CP17 -> 0 | CR17: =CP17+CQ17 -> 0 | CT17: =(CR17-CS17)+CN17 -> 0 | CW17: =$AF$17*CV17 -> 0 | CX17: =CV17+CW17 -> 0 | CZ17: =(CX17-CY17)+CT17 -> 0 | DA17: =SUM(AG17,AM17,AS17,AY17,BE17,BK17,BQ17,BW17,CC17,CI17,CO17,CU17) -> 0 | DB17: =SUM(AH17,AN17,AT17,AZ17,BF17,BL17,BR17,BX17,CD17,CJ17,CP17,CV17) -> 0 | DC17: =SUM(AI17,AO17,AU17,BA17,BG17,BM17,BS17,BY17,CE17,CK17,CQ17,CW17) -> 0 | DD17: =SUM(AJ17,AP17,AV17,BB17,BH17,BN17,BT17,BZ17,CF17,CL17,CR17,CX17) -> 0 | DE17: =SUM(AK17,AQ17,AW17,BC17,BI17,BO17,BU17,CA17,CG17,CM17,CS17,CY17) -> 0 | DF17: =CZ17 -> 0
A18: ='Group-Savings'!A18 -> 0 | B18: ='Group-Savings'!B18 -> 0 | C18: ='Group-Savings'!C18 -> 0 | D18: ='Group-Savings'!D18 -> 0 | E18: ='Group-Savings'!E18 -> 0 | F18: ='Group-Savings'!F18 -> 0 | G18: ='Group-Savings'!G18 -> 0 | H18: ='Group-Savings'!H18 -> 0 | ... L18: ='Group-Savings'!L18 -> 0 | M18: =K18+L18 -> 0 | O18: 28 | R18: 19 | S18: 10 | V18: =S18*U18 -> 0 | W18: 425000 | X18: 440000 | Y18: =W18-X18 -> -15000 | Z18: 98000 | AI18: =$AF$18*AH18 -> 0 | AJ18: =AH18+AI18 -> 0 | AL18: =AJ18-AK18 -> 0 | AO18: =$AF$18*AN18 -> 0 | AP18: =AN18+AO18 -> 0 | AR18: =(AP18-AQ18)+AL18 -> 0 | AU18: =$AF$18*AT18 -> 0 | AV18: =AT18+AU18 -> 0 | AX18: =(AV18-AW18)+AR18 -> 0 | BA18: =$AF$18*AZ18 -> 0 | BB18: =AZ18+BA18 -> 0 | BD18: =(BB18-BC18)+AX18 -> 0 | BG18: =$AF$18*BF18 -> 0 | BH18: =BF18+BG18 -> 0 | BJ18: =(BH18-BI18)+BD18 -> 0 | BM18: =$AF$18*BL18 -> 0 | BN18: =BL18+BM18 -> 0 | BP18: =(BN18-BO18)+BJ18 -> 0 | BS18: =$AF$18*BR18 -> 0 | BT18: =BR18+BS18 -> 0 | BV18: =(BT18-BU18)+BP18 -> 0 | BY18: =$AF$18*BX18 -> 0 | BZ18: =BX18+BY18 -> 0 | CB18: =(BZ18-CA18)+BV18 -> 0 | CE18: =$AF$18*CD18 -> 0 | CF18: =CD18+CE18 -> 0 | CH18: =(CF18-CG18)+CB18 -> 0 | CK18: =$AF$18*CJ18 -> 0 | CL18: =CJ18+CK18 -> 0 | CN18: =(CL18-CM18)+CH18 -> 0 | CQ18: =$AF$18*CP18 -> 0 | CR18: =CP18+CQ18 -> 0 | CT18: =(CR18-CS18)+CN18 -> 0 | CW18: =$AF$18*CV18 -> 0 | CX18: =CV18+CW18 -> 0 | CZ18: =(CX18-CY18)+CT18 -> 0 | DA18: =SUM(AG18,AM18,AS18,AY18,BE18,BK18,BQ18,BW18,CC18,CI18,CO18,CU18) -> 0 | DB18: =SUM(AH18,AN18,AT18,AZ18,BF18,BL18,BR18,BX18,CD18,CJ18,CP18,CV18) -> 0 | DC18: =SUM(AI18,AO18,AU18,BA18,BG18,BM18,BS18,BY18,CE18,CK18,CQ18,CW18) -> 0 | DD18: =SUM(AJ18,AP18,AV18,BB18,BH18,BN18,BT18,BZ18,CF18,CL18,CR18,CX18) -> 0 | DE18: =SUM(AK18,AQ18,AW18,BC18,BI18,BO18,BU18,CA18,CG18,CM18,CS18,CY18) -> 0 | DF18: =CZ18 -> 0
A19: ='Group-Savings'!A19 -> 0 | B19: ='Group-Savings'!B19 -> 0 | C19: ='Group-Savings'!C19 -> 0 | D19: ='Group-Savings'!D19 -> 0 | E19: ='Group-Savings'!E19 -> 0 | F19: ='Group-Savings'!F19 -> 0 | G19: ='Group-Savings'!G19 -> 0 | H19: ='Group-Savings'!H19 -> 0 | ... L19: ='Group-Savings'!L19 -> 0 | M19: =K19+L19 -> 0 | O19: 52 | R19: 32 | S19: 10 | V19: =S19*U19 -> 0 | W19: 2483900 | X19: 2483900 | Y19: =W19-X19 -> 0 | Z19: 189800 | AI19: =$AF$19*AH19 -> 0 | AJ19: =AH19+AI19 -> 0 | AL19: =AJ19-AK19 -> 0 | AO19: =$AF$19*AN19 -> 0 | AP19: =AN19+AO19 -> 0 | AR19: =(AP19-AQ19)+AL19 -> 0 | AU19: =$AF$19*AT19 -> 0 | AV19: =AT19+AU19 -> 0 | AX19: =(AV19-AW19)+AR19 -> 0 | BA19: =$AF$19*AZ19 -> 0 | BB19: =AZ19+BA19 -> 0 | BD19: =(BB19-BC19)+AX19 -> 0 | BG19: =$AF$19*BF19 -> 0 | BH19: =BF19+BG19 -> 0 | BJ19: =(BH19-BI19)+BD19 -> 0 | BM19: =$AF$19*BL19 -> 0 | BN19: =BL19+BM19 -> 0 | BP19: =(BN19-BO19)+BJ19 -> 0 | BS19: =$AF$19*BR19 -> 0 | BT19: =BR19+BS19 -> 0 | BV19: =(BT19-BU19)+BP19 -> 0 | BY19: =$AF$19*BX19 -> 0 | BZ19: =BX19+BY19 -> 0 | CB19: =(BZ19-CA19)+BV19 -> 0 | CE19: =$AF$19*CD19 -> 0 | CF19: =CD19+CE19 -> 0 | CH19: =(CF19-CG19)+CB19 -> 0 | CK19: =$AF$19*CJ19 -> 0 | CL19: =CJ19+CK19 -> 0 | CN19: =(CL19-CM19)+CH19 -> 0 | CQ19: =$AF$19*CP19 -> 0 | CR19: =CP19+CQ19 -> 0 | CT19: =(CR19-CS19)+CN19 -> 0 | CW19: =$AF$19*CV19 -> 0 | CX19: =CV19+CW19 -> 0 | CZ19: =(CX19-CY19)+CT19 -> 0 | DA19: =SUM(AG19,AM19,AS19,AY19,BE19,BK19,BQ19,BW19,CC19,CI19,CO19,CU19) -> 0 | DB19: =SUM(AH19,AN19,AT19,AZ19,BF19,BL19,BR19,BX19,CD19,CJ19,CP19,CV19) -> 0 | DC19: =SUM(AI19,AO19,AU19,BA19,BG19,BM19,BS19,BY19,CE19,CK19,CQ19,CW19) -> 0 | DD19: =SUM(AJ19,AP19,AV19,BB19,BH19,BN19,BT19,BZ19,CF19,CL19,CR19,CX19) -> 0 | DE19: =SUM(AK19,AQ19,AW19,BC19,BI19,BO19,BU19,CA19,CG19,CM19,CS19,CY19) -> 0 | DF19: =CZ19 -> 0
A20: ='Group-Savings'!A20 -> 0 | B20: ='Group-Savings'!B20 -> 0 | C20: ='Group-Savings'!C20 -> 0 | D20: ='Group-Savings'!D20 -> 0 | E20: ='Group-Savings'!E20 -> 0 | F20: ='Group-Savings'!F20 -> 0 | G20: ='Group-Savings'!G20 -> 0 | H20: ='Group-Savings'!H20 -> 0 | ... L20: ='Group-Savings'!L20 -> 0 | M20: =K20+L20 -> 0 | O20: 28 | R20: 26 | S20: 10 | V20: =S20*U20 -> 0 | W20: 4775000 | X20: 4775000 | Y20: =W20-X20 -> 0 | Z20: 280000 | AI20: =$AF$20*AH20 -> 0 | AJ20: =AH20+AI20 -> 0 | AL20: =AJ20-AK20 -> 0 | AO20: =$AF$20*AN20 -> 0 | AP20: =AN20+AO20 -> 0 | AR20: =(AP20-AQ20)+AL20 -> 0 | AU20: =$AF$20*AT20 -> 0 | AV20: =AT20+AU20 -> 0 | AX20: =(AV20-AW20)+AR20 -> 0 | BA20: =$AF$20*AZ20 -> 0 | BB20: =AZ20+BA20 -> 0 | BD20: =(BB20-BC20)+AX20 -> 0 | BG20: =$AF$20*BF20 -> 0 | BH20: =BF20+BG20 -> 0 | BJ20: =(BH20-BI20)+BD20 -> 0 | BM20: =$AF$20*BL20 -> 0 | BN20: =BL20+BM20 -> 0 | BP20: =(BN20-BO20)+BJ20 -> 0 | BS20: =$AF$20*BR20 -> 0 | BT20: =BR20+BS20 -> 0 | BV20: =(BT20-BU20)+BP20 -> 0 | BY20: =$AF$20*BX20 -> 0 | BZ20: =BX20+BY20 -> 0 | CB20: =(BZ20-CA20)+BV20 -> 0 | CE20: =$AF$20*CD20 -> 0 | CF20: =CD20+CE20 -> 0 | CH20: =(CF20-CG20)+CB20 -> 0 | CK20: =$AF$20*CJ20 -> 0 | CL20: =CJ20+CK20 -> 0 | CN20: =(CL20-CM20)+CH20 -> 0 | CQ20: =$AF$20*CP20 -> 0 | CR20: =CP20+CQ20 -> 0 | CT20: =(CR20-CS20)+CN20 -> 0 | CW20: =$AF$20*CV20 -> 0 | CX20: =CV20+CW20 -> 0 | CZ20: =(CX20-CY20)+CT20 -> 0 | DA20: =SUM(AG20,AM20,AS20,AY20,BE20,BK20,BQ20,BW20,CC20,CI20,CO20,CU20) -> 0 | DB20: =SUM(AH20,AN20,AT20,AZ20,BF20,BL20,BR20,BX20,CD20,CJ20,CP20,CV20) -> 0 | DC20: =SUM(AI20,AO20,AU20,BA20,BG20,BM20,BS20,BY20,CE20,CK20,CQ20,CW20) -> 0 | DD20: =SUM(AJ20,AP20,AV20,BB20,BH20,BN20,BT20,BZ20,CF20,CL20,CR20,CX20) -> 0 | DE20: =SUM(AK20,AQ20,AW20,BC20,BI20,BO20,BU20,CA20,CG20,CM20,CS20,CY20) -> 0 | DF20: =CZ20 -> 0
A21: ='Group-Savings'!A21 -> 0 | B21: ='Group-Savings'!B21 -> 0 | C21: ='Group-Savings'!C21 -> 0 | D21: ='Group-Savings'!D21 -> 0 | E21: ='Group-Savings'!E21 -> 0 | F21: ='Group-Savings'!F21 -> 0 | G21: ='Group-Savings'!G21 -> 0 | H21: ='Group-Savings'!H21 -> 0 | ... L21: ='Group-Savings'!L21 -> 0 | M21: =K21+L21 -> 0 | O21: 10 | R21: 19 | S21: 10 | U21: 0 | V21: =S21*U21 -> 0 | W21: 6001000 | X21: 5001000 | Y21: =W21-X21 -> 1000000 | Z21: 65000 | AI21: =$AF$21*AH21 -> 0 | AJ21: =AH21+AI21 -> 0 | AL21: =AJ21-AK21 -> 0 | AO21: =$AF$21*AN21 -> 0 | AP21: =AN21+AO21 -> 0 | AR21: =(AP21-AQ21)+AL21 -> 0 | AU21: =$AF$21*AT21 -> 0 | AV21: =AT21+AU21 -> 0 | AX21: =(AV21-AW21)+AR21 -> 0 | BA21: =$AF$21*AZ21 -> 0 | BB21: =AZ21+BA21 -> 0 | BD21: =(BB21-BC21)+AX21 -> 0 | BG21: =$AF$21*BF21 -> 0 | BH21: =BF21+BG21 -> 0 | BJ21: =(BH21-BI21)+BD21 -> 0 | BM21: =$AF$21*BL21 -> 0 | BN21: =BL21+BM21 -> 0 | BP21: =(BN21-BO21)+BJ21 -> 0 | BS21: =$AF$21*BR21 -> 0 | BT21: =BR21+BS21 -> 0 | BV21: =(BT21-BU21)+BP21 -> 0 | BY21: =$AF$21*BX21 -> 0 | BZ21: =BX21+BY21 -> 0 | CB21: =(BZ21-CA21)+BV21 -> 0 | CE21: =$AF$21*CD21 -> 0 | CF21: =CD21+CE21 -> 0 | CH21: =(CF21-CG21)+CB21 -> 0 | CK21: =$AF$21*CJ21 -> 0 | CL21: =CJ21+CK21 -> 0 | CN21: =(CL21-CM21)+CH21 -> 0 | CQ21: =$AF$21*CP21 -> 0 | CR21: =CP21+CQ21 -> 0 | CT21: =(CR21-CS21)+CN21 -> 0 | CW21: =$AF$21*CV21 -> 0 | CX21: =CV21+CW21 -> 0 | CZ21: =(CX21-CY21)+CT21 -> 0 | DA21: =SUM(AG21,AM21,AS21,AY21,BE21,BK21,BQ21,BW21,CC21,CI21,CO21,CU21) -> 0 | DB21: =SUM(AH21,AN21,AT21,AZ21,BF21,BL21,BR21,BX21,CD21,CJ21,CP21,CV21) -> 0 | DC21: =SUM(AI21,AO21,AU21,BA21,BG21,BM21,BS21,BY21,CE21,CK21,CQ21,CW21) -> 0 | DD21: =SUM(AJ21,AP21,AV21,BB21,BH21,BN21,BT21,BZ21,CF21,CL21,CR21,CX21) -> 0 | DE21: =SUM(AK21,AQ21,AW21,BC21,BI21,BO21,BU21,CA21,CG21,CM21,CS21,CY21) -> 0 | DF21: =CZ21 -> 0
A22: ='Group-Savings'!A22 -> 0 | B22: ='Group-Savings'!B22 -> 0 | C22: ='Group-Savings'!C22 -> 0 | D22: ='Group-Savings'!D22 -> 0 | E22: ='Group-Savings'!E22 -> 0 | F22: ='Group-Savings'!F22 -> 0 | G22: ='Group-Savings'!G22 -> 0 | H22: ='Group-Savings'!H22 -> 0 | ... L22: ='Group-Savings'!L22 -> 0 | M22: =K22+L22 -> 0 | O22: 26 | R22: 12 | S22: 10 | V22: =S22*U22 -> 0 | W22: 275000 | X22: 275000 | Y22: =W22-X22 -> 0 | Z22: 130000 | AI22: =$AF$22*AH22 -> 0 | AJ22: =AH22+AI22 -> 0 | AL22: =AJ22-AK22 -> 0 | AO22: =$AF$22*AN22 -> 0 | AP22: =AN22+AO22 -> 0 | AR22: =(AP22-AQ22)+AL22 -> 0 | AU22: =$AF$22*AT22 -> 0 | AV22: =AT22+AU22 -> 0 | AX22: =(AV22-AW22)+AR22 -> 0 | BA22: =$AF$22*AZ22 -> 0 | BB22: =AZ22+BA22 -> 0 | BD22: =(BB22-BC22)+AX22 -> 0 | BG22: =$AF$22*BF22 -> 0 | BH22: =BF22+BG22 -> 0 | BJ22: =(BH22-BI22)+BD22 -> 0 | BM22: =$AF$22*BL22 -> 0 | BN22: =BL22+BM22 -> 0 | BP22: =(BN22-BO22)+BJ22 -> 0 | BS22: =$AF$22*BR22 -> 0 | BT22: =BR22+BS22 -> 0 | BV22: =(BT22-BU22)+BP22 -> 0 | BY22: =$AF$22*BX22 -> 0 | BZ22: =BX22+BY22 -> 0 | CB22: =(BZ22-CA22)+BV22 -> 0 | CE22: =$AF$22*CD22 -> 0 | CF22: =CD22+CE22 -> 0 | CH22: =(CF22-CG22)+CB22 -> 0 | CK22: =$AF$22*CJ22 -> 0 | CL22: =CJ22+CK22 -> 0 | CN22: =(CL22-CM22)+CH22 -> 0 | CQ22: =$AF$22*CP22 -> 0 | CR22: =CP22+CQ22 -> 0 | CT22: =(CR22-CS22)+CN22 -> 0 | CW22: =$AF$22*CV22 -> 0 | CX22: =CV22+CW22 -> 0 | CZ22: =(CX22-CY22)+CT22 -> 0 | DA22: =SUM(AG22,AM22,AS22,AY22,BE22,BK22,BQ22,BW22,CC22,CI22,CO22,CU22) -> 0 | DB22: =SUM(AH22,AN22,AT22,AZ22,BF22,BL22,BR22,BX22,CD22,CJ22,CP22,CV22) -> 0 | DC22: =SUM(AI22,AO22,AU22,BA22,BG22,BM22,BS22,BY22,CE22,CK22,CQ22,CW22) -> 0 | DD22: =SUM(AJ22,AP22,AV22,BB22,BH22,BN22,BT22,BZ22,CF22,CL22,CR22,CX22) -> 0 | DE22: =SUM(AK22,AQ22,AW22,BC22,BI22,BO22,BU22,CA22,CG22,CM22,CS22,CY22) -> 0 | DF22: =CZ22 -> 0
A23: ='Group-Savings'!A23 -> 0 | B23: ='Group-Savings'!B23 -> 0 | C23: ='Group-Savings'!C23 -> 0 | D23: ='Group-Savings'!D23 -> 0 | E23: ='Group-Savings'!E23 -> 0 | F23: ='Group-Savings'!F23 -> 0 | G23: ='Group-Savings'!G23 -> 0 | H23: ='Group-Savings'!H23 -> 0 | ... L23: ='Group-Savings'!L23 -> 0 | M23: =K23+L23 -> 0 | O23: 41 | R23: 28 | S23: 10 | V23: =S23*U23 -> 0 | W23: 1306000 | X23: 457000 | Y23: =W23-X23 -> 849000 | Z23: 490000 | AI23: =$AF$23*AH23 -> 0 | AJ23: =AH23+AI23 -> 0 | AL23: =AJ23-AK23 -> 0 | AO23: =$AF$23*AN23 -> 0 | AP23: =AN23+AO23 -> 0 | AR23: =(AP23-AQ23)+AL23 -> 0 | AU23: =$AF$23*AT23 -> 0 | AV23: =AT23+AU23 -> 0 | AX23: =(AV23-AW23)+AR23 -> 0 | BA23: =$AF$23*AZ23 -> 0 | BB23: =AZ23+BA23 -> 0 | BD23: =(BB23-BC23)+AX23 -> 0 | BG23: =$AF$23*BF23 -> 0 | BH23: =BF23+BG23 -> 0 | BJ23: =(BH23-BI23)+BD23 -> 0 | BM23: =$AF$23*BL23 -> 0 | BN23: =BL23+BM23 -> 0 | BP23: =(BN23-BO23)+BJ23 -> 0 | BS23: =$AF$23*BR23 -> 0 | BT23: =BR23+BS23 -> 0 | BV23: =(BT23-BU23)+BP23 -> 0 | BY23: =$AF$23*BX23 -> 0 | BZ23: =BX23+BY23 -> 0 | CB23: =(BZ23-CA23)+BV23 -> 0 | CE23: =$AF$23*CD23 -> 0 | CF23: =CD23+CE23 -> 0 | CH23: =(CF23-CG23)+CB23 -> 0 | CK23: =$AF$23*CJ23 -> 0 | CL23: =CJ23+CK23 -> 0 | CN23: =(CL23-CM23)+CH23 -> 0 | CQ23: =$AF$23*CP23 -> 0 | CR23: =CP23+CQ23 -> 0 | CT23: =(CR23-CS23)+CN23 -> 0 | CW23: =$AF$23*CV23 -> 0 | CX23: =CV23+CW23 -> 0 | CZ23: =(CX23-CY23)+CT23 -> 0 | DA23: =SUM(AG23,AM23,AS23,AY23,BE23,BK23,BQ23,BW23,CC23,CI23,CO23,CU23) -> 0 | DB23: =SUM(AH23,AN23,AT23,AZ23,BF23,BL23,BR23,BX23,CD23,CJ23,CP23,CV23) -> 0 | DC23: =SUM(AI23,AO23,AU23,BA23,BG23,BM23,BS23,BY23,CE23,CK23,CQ23,CW23) -> 0 | DD23: =SUM(AJ23,AP23,AV23,BB23,BH23,BN23,BT23,BZ23,CF23,CL23,CR23,CX23) -> 0 | DE23: =SUM(AK23,AQ23,AW23,BC23,BI23,BO23,BU23,CA23,CG23,CM23,CS23,CY23) -> 0 | DF23: =CZ23 -> 0
A24: ='Group-Savings'!A24 -> 0 | B24: ='Group-Savings'!B24 -> 0 | C24: ='Group-Savings'!C24 -> 0 | D24: ='Group-Savings'!D24 -> 0 | E24: ='Group-Savings'!E24 -> 0 | F24: ='Group-Savings'!F24 -> 0 | G24: ='Group-Savings'!G24 -> 0 | H24: ='Group-Savings'!H24 -> 0 | ... L24: ='Group-Savings'!L24 -> 0 | M24: =K24+L24 -> 0 | O24: 9 | R24: 7 | S24: 10 | U24: 0 | V24: =S24*U24 -> 0 | W24: 247400 | X24: 247000 | Y24: =W24-X24 -> 400 | Z24: 45000 | AI24: =$AF$24*AH24 -> 0 | AJ24: =AH24+AI24 -> 0 | AL24: =AJ24-AK24 -> 0 | AO24: =$AF$24*AN24 -> 0 | AP24: =AN24+AO24 -> 0 | AR24: =(AP24-AQ24)+AL24 -> 0 | AU24: =$AF$24*AT24 -> 0 | AV24: =AT24+AU24 -> 0 | AX24: =(AV24-AW24)+AR24 -> 0 | BA24: =$AF$24*AZ24 -> 0 | BB24: =AZ24+BA24 -> 0 | BD24: =(BB24-BC24)+AX24 -> 0 | BG24: =$AF$24*BF24 -> 0 | BH24: =BF24+BG24 -> 0 | BJ24: =(BH24-BI24)+BD24 -> 0 | BM24: =$AF$24*BL24 -> 0 | BN24: =BL24+BM24 -> 0 | BP24: =(BN24-BO24)+BJ24 -> 0 | BS24: =$AF$24*BR24 -> 0 | BT24: =BR24+BS24 -> 0 | BV24: =(BT24-BU24)+BP24 -> 0 | BY24: =$AF$24*BX24 -> 0 | BZ24: =BX24+BY24 -> 0 | CB24: =(BZ24-CA24)+BV24 -> 0 | CE24: =$AF$24*CD24 -> 0 | CF24: =CD24+CE24 -> 0 | CH24: =(CF24-CG24)+CB24 -> 0 | CK24: =$AF$24*CJ24 -> 0 | CL24: =CJ24+CK24 -> 0 | CN24: =(CL24-CM24)+CH24 -> 0 | CQ24: =$AF$24*CP24 -> 0 | CR24: =CP24+CQ24 -> 0 | CT24: =(CR24-CS24)+CN24 -> 0 | CW24: =$AF$24*CV24 -> 0 | CX24: =CV24+CW24 -> 0 | CZ24: =(CX24-CY24)+CT24 -> 0 | DA24: =SUM(AG24,AM24,AS24,AY24,BE24,BK24,BQ24,BW24,CC24,CI24,CO24,CU24) -> 0 | DB24: =SUM(AH24,AN24,AT24,AZ24,BF24,BL24,BR24,BX24,CD24,CJ24,CP24,CV24) -> 0 | DC24: =SUM(AI24,AO24,AU24,BA24,BG24,BM24,BS24,BY24,CE24,CK24,CQ24,CW24) -> 0 | DD24: =SUM(AJ24,AP24,AV24,BB24,BH24,BN24,BT24,BZ24,CF24,CL24,CR24,CX24) -> 0 | DE24: =SUM(AK24,AQ24,AW24,BC24,BI24,BO24,BU24,CA24,CG24,CM24,CS24,CY24) -> 0 | DF24: =CZ24 -> 0
A25: ='Group-Savings'!A25 -> 0 | B25: ='Group-Savings'!B25 -> 0 | C25: ='Group-Savings'!C25 -> 0 | D25: ='Group-Savings'!D25 -> 0 | E25: ='Group-Savings'!E25 -> 0 | F25: ='Group-Savings'!F25 -> 0 | G25: ='Group-Savings'!G25 -> 0 | H25: ='Group-Savings'!H25 -> 0 | ... L25: ='Group-Savings'!L25 -> 0 | M25: =K25+L25 -> 0 | O25: 47 | R25: 24 | S25: 10 | V25: =S25*U25 -> 0 | W25: 6083000 | X25: 6083000 | Y25: =W25-X25 -> 0 | Z25: 282000 | AI25: =$AF$25*AH25 -> 0 | AJ25: =AH25+AI25 -> 0 | AL25: =AJ25-AK25 -> 0 | AO25: =$AF$25*AN25 -> 0 | AP25: =AN25+AO25 -> 0 | AR25: =(AP25-AQ25)+AL25 -> 0 | AU25: =$AF$25*AT25 -> 0 | AV25: =AT25+AU25 -> 0 | AX25: =(AV25-AW25)+AR25 -> 0 | BA25: =$AF$25*AZ25 -> 0 | BB25: =AZ25+BA25 -> 0 | BD25: =(BB25-BC25)+AX25 -> 0 | BG25: =$AF$25*BF25 -> 0 | BH25: =BF25+BG25 -> 0 | BJ25: =(BH25-BI25)+BD25 -> 0 | BM25: =$AF$25*BL25 -> 0 | BN25: =BL25+BM25 -> 0 | BP25: =(BN25-BO25)+BJ25 -> 0 | BS25: =$AF$25*BR25 -> 0 | BT25: =BR25+BS25 -> 0 | BV25: =(BT25-BU25)+BP25 -> 0 | BY25: =$AF$25*BX25 -> 0 | BZ25: =BX25+BY25 -> 0 | CB25: =(BZ25-CA25)+BV25 -> 0 | CE25: =$AF$25*CD25 -> 0 | CF25: =CD25+CE25 -> 0 | CH25: =(CF25-CG25)+CB25 -> 0 | CK25: =$AF$25*CJ25 -> 0 | CL25: =CJ25+CK25 -> 0 | CN25: =(CL25-CM25)+CH25 -> 0 | CQ25: =$AF$25*CP25 -> 0 | CR25: =CP25+CQ25 -> 0 | CT25: =(CR25-CS25)+CN25 -> 0 | CW25: =$AF$25*CV25 -> 0 | CX25: =CV25+CW25 -> 0 | CZ25: =(CX25-CY25)+CT25 -> 0 | DA25: =SUM(AG25,AM25,AS25,AY25,BE25,BK25,BQ25,BW25,CC25,CI25,CO25,CU25) -> 0 | DB25: =SUM(AH25,AN25,AT25,AZ25,BF25,BL25,BR25,BX25,CD25,CJ25,CP25,CV25) -> 0 | DC25: =SUM(AI25,AO25,AU25,BA25,BG25,BM25,BS25,BY25,CE25,CK25,CQ25,CW25) -> 0 | DD25: =SUM(AJ25,AP25,AV25,BB25,BH25,BN25,BT25,BZ25,CF25,CL25,CR25,CX25) -> 0 | DE25: =SUM(AK25,AQ25,AW25,BC25,BI25,BO25,BU25,CA25,CG25,CM25,CS25,CY25) -> 0 | DF25: =CZ25 -> 0
A26: ='Group-Savings'!A26 -> 0 | B26: ='Group-Savings'!B26 -> 0 | C26: ='Group-Savings'!C26 -> 0 | D26: ='Group-Savings'!D26 -> 0 | E26: ='Group-Savings'!E26 -> 0 | F26: ='Group-Savings'!F26 -> 0 | G26: ='Group-Savings'!G26 -> 0 | H26: ='Group-Savings'!H26 -> 0 | ... L26: ='Group-Savings'!L26 -> 0 | M26: =K26+L26 -> 0 | O26: 31 | R26: 12 | S26: 10 | V26: =S26*U26 -> 0 | W26: 400000 | X26: 400000 | Y26: =W26-X26 -> 0 | Z26: 92000 | AI26: =$AF$26*AH26 -> 0 | AJ26: =AH26+AI26 -> 0 | AL26: =AJ26-AK26 -> 0 | AO26: =$AF$26*AN26 -> 0 | AP26: =AN26+AO26 -> 0 | AR26: =(AP26-AQ26)+AL26 -> 0 | AU26: =$AF$26*AT26 -> 0 | AV26: =AT26+AU26 -> 0 | AX26: =(AV26-AW26)+AR26 -> 0 | BA26: =$AF$26*AZ26 -> 0 | BB26: =AZ26+BA26 -> 0 | BD26: =(BB26-BC26)+AX26 -> 0 | BG26: =$AF$26*BF26 -> 0 | BH26: =BF26+BG26 -> 0 | BJ26: =(BH26-BI26)+BD26 -> 0 | BM26: =$AF$26*BL26 -> 0 | BN26: =BL26+BM26 -> 0 | BP26: =(BN26-BO26)+BJ26 -> 0 | BS26: =$AF$26*BR26 -> 0 | BT26: =BR26+BS26 -> 0 | BV26: =(BT26-BU26)+BP26 -> 0 | BY26: =$AF$26*BX26 -> 0 | BZ26: =BX26+BY26 -> 0 | CB26: =(BZ26-CA26)+BV26 -> 0 | CE26: =$AF$26*CD26 -> 0 | CF26: =CD26+CE26 -> 0 | CH26: =(CF26-CG26)+CB26 -> 0 | CK26: =$AF$26*CJ26 -> 0 | CL26: =CJ26+CK26 -> 0 | CN26: =(CL26-CM26)+CH26 -> 0 | CQ26: =$AF$26*CP26 -> 0 | CR26: =CP26+CQ26 -> 0 | CT26: =(CR26-CS26)+CN26 -> 0 | CW26: =$AF$26*CV26 -> 0 | CX26: =CV26+CW26 -> 0 | CZ26: =(CX26-CY26)+CT26 -> 0 | DA26: =SUM(AG26,AM26,AS26,AY26,BE26,BK26,BQ26,BW26,CC26,CI26,CO26,CU26) -> 0 | DB26: =SUM(AH26,AN26,AT26,AZ26,BF26,BL26,BR26,BX26,CD26,CJ26,CP26,CV26) -> 0 | DC26: =SUM(AI26,AO26,AU26,BA26,BG26,BM26,BS26,BY26,CE26,CK26,CQ26,CW26) -> 0 | DD26: =SUM(AJ26,AP26,AV26,BB26,BH26,BN26,BT26,BZ26,CF26,CL26,CR26,CX26) -> 0 | DE26: =SUM(AK26,AQ26,AW26,BC26,BI26,BO26,BU26,CA26,CG26,CM26,CS26,CY26) -> 0 | DF26: =CZ26 -> 0
